[2022-10-21 15:27:22,612] {taskinstance.py:1159} INFO - Dependencies all met for <TaskInstance: 1_init_once_seed_data.load_seed_data_once manual__2022-10-21T15:26:20.949989+00:00 [queued]>
[2022-10-21 15:27:22,727] {taskinstance.py:1159} INFO - Dependencies all met for <TaskInstance: 1_init_once_seed_data.load_seed_data_once manual__2022-10-21T15:26:20.949989+00:00 [queued]>
[2022-10-21 15:27:24,064] {taskinstance.py:1356} INFO - 
--------------------------------------------------------------------------------
[2022-10-21 15:27:24,070] {taskinstance.py:1357} INFO - Starting attempt 1 of 1
[2022-10-21 15:27:24,082] {taskinstance.py:1358} INFO - 
--------------------------------------------------------------------------------
[2022-10-21 15:28:07,870] {taskinstance.py:1377} INFO - Executing <Task(BashOperator): load_seed_data_once> on 2022-10-21 15:26:20.949989+00:00
[2022-10-21 15:28:07,922] {standard_task_runner.py:52} INFO - Started process 124 to run task
[2022-10-21 15:28:07,963] {standard_task_runner.py:79} INFO - Running: ['***', 'tasks', 'run', '1_init_once_seed_data', 'load_seed_data_once', 'manual__2022-10-21T15:26:20.949989+00:00', '--job-id', '103', '--raw', '--subdir', 'DAGS_FOLDER/init.py', '--cfg-path', '/tmp/tmpznrac_dm', '--error-file', '/tmp/tmpuqwbdnju']
[2022-10-21 15:28:07,972] {standard_task_runner.py:80} INFO - Job 103: Subtask load_seed_data_once
[2022-10-21 15:28:09,678] {task_command.py:369} INFO - Running <TaskInstance: 1_init_once_seed_data.load_seed_data_once manual__2022-10-21T15:26:20.949989+00:00 [running]> on host 79cac217208b
[2022-10-21 15:28:41,397] {taskinstance.py:1571} INFO - Exporting the following env vars:
AIRFLOW_CTX_DAG_OWNER=***
AIRFLOW_CTX_DAG_ID=1_init_once_seed_data
AIRFLOW_CTX_TASK_ID=load_seed_data_once
AIRFLOW_CTX_EXECUTION_DATE=2022-10-21T15:26:20.949989+00:00
AIRFLOW_CTX_TRY_NUMBER=1
AIRFLOW_CTX_DAG_RUN_ID=manual__2022-10-21T15:26:20.949989+00:00
[2022-10-21 15:28:41,414] {subprocess.py:62} INFO - Tmp dir root location: 
 /tmp
[2022-10-21 15:28:42,020] {subprocess.py:74} INFO - Running command: ['bash', '-c', 'cd /dbt && dbt seed --profiles-dir .']
[2022-10-21 15:28:42,103] {subprocess.py:85} INFO - Output:
[2022-10-21 15:28:42,120] {subprocess.py:92} INFO - bash: line 1: dbt: command not found
[2022-10-21 15:28:42,121] {subprocess.py:96} INFO - Command exited with return code 127
[2022-10-21 15:28:42,194] {taskinstance.py:1889} ERROR - Task failed with exception
Traceback (most recent call last):
  File "/home/airflow/.local/lib/python3.7/site-packages/airflow/operators/bash.py", line 195, in execute
    f'Bash command failed. The command returned a non-zero exit code {result.exit_code}.'
airflow.exceptions.AirflowException: Bash command failed. The command returned a non-zero exit code 127.
[2022-10-21 15:28:42,218] {taskinstance.py:1400} INFO - Marking task as FAILED. dag_id=1_init_once_seed_data, task_id=load_seed_data_once, execution_date=20221021T152620, start_date=20221021T152722, end_date=20221021T152842
[2022-10-21 15:28:42,330] {standard_task_runner.py:97} ERROR - Failed to execute job 103 for task load_seed_data_once (Bash command failed. The command returned a non-zero exit code 127.; 124)
[2022-10-21 15:28:42,423] {local_task_job.py:156} INFO - Task exited with return code 1
[2022-10-21 15:28:42,570] {local_task_job.py:273} INFO - 0 downstream tasks scheduled from follow-on schedule check
