[2022-10-20 15:32:20,120] {taskinstance.py:1159} INFO - Dependencies all met for <TaskInstance: 1_init_once_seed_data.load_seed_data_once manual__2022-10-20T15:32:17.375166+00:00 [queued]>
[2022-10-20 15:32:20,159] {taskinstance.py:1159} INFO - Dependencies all met for <TaskInstance: 1_init_once_seed_data.load_seed_data_once manual__2022-10-20T15:32:17.375166+00:00 [queued]>
[2022-10-20 15:32:20,160] {taskinstance.py:1356} INFO - 
--------------------------------------------------------------------------------
[2022-10-20 15:32:20,168] {taskinstance.py:1357} INFO - Starting attempt 1 of 1
[2022-10-20 15:32:20,171] {taskinstance.py:1358} INFO - 
--------------------------------------------------------------------------------
[2022-10-20 15:32:20,278] {taskinstance.py:1377} INFO - Executing <Task(BashOperator): load_seed_data_once> on 2022-10-20 15:32:17.375166+00:00
[2022-10-20 15:32:20,298] {standard_task_runner.py:52} INFO - Started process 1454 to run task
[2022-10-20 15:32:20,343] {standard_task_runner.py:79} INFO - Running: ['***', 'tasks', 'run', '1_init_once_seed_data', 'load_seed_data_once', 'manual__2022-10-20T15:32:17.375166+00:00', '--job-id', '12', '--raw', '--subdir', 'DAGS_FOLDER/init.py', '--cfg-path', '/tmp/tmpf_le9ytg', '--error-file', '/tmp/tmpnji4mv1k']
[2022-10-20 15:32:20,348] {standard_task_runner.py:80} INFO - Job 12: Subtask load_seed_data_once
[2022-10-20 15:32:20,890] {task_command.py:369} INFO - Running <TaskInstance: 1_init_once_seed_data.load_seed_data_once manual__2022-10-20T15:32:17.375166+00:00 [running]> on host e6f75c36125c
[2022-10-20 15:32:22,057] {taskinstance.py:1571} INFO - Exporting the following env vars:
AIRFLOW_CTX_DAG_OWNER=***
AIRFLOW_CTX_DAG_ID=1_init_once_seed_data
AIRFLOW_CTX_TASK_ID=load_seed_data_once
AIRFLOW_CTX_EXECUTION_DATE=2022-10-20T15:32:17.375166+00:00
AIRFLOW_CTX_TRY_NUMBER=1
AIRFLOW_CTX_DAG_RUN_ID=manual__2022-10-20T15:32:17.375166+00:00
[2022-10-20 15:32:22,076] {subprocess.py:62} INFO - Tmp dir root location: 
 /tmp
[2022-10-20 15:32:22,090] {subprocess.py:74} INFO - Running command: ['bash', '-c', 'cd /dbt_project && dbt seed --profiles-dir .']
[2022-10-20 15:32:22,180] {subprocess.py:85} INFO - Output:
[2022-10-20 15:32:22,242] {subprocess.py:92} INFO - bash: line 1: cd: /dbt_project: No such file or directory
[2022-10-20 15:32:22,244] {subprocess.py:96} INFO - Command exited with return code 1
[2022-10-20 15:32:22,379] {taskinstance.py:1889} ERROR - Task failed with exception
Traceback (most recent call last):
  File "/home/airflow/.local/lib/python3.7/site-packages/airflow/operators/bash.py", line 195, in execute
    f'Bash command failed. The command returned a non-zero exit code {result.exit_code}.'
airflow.exceptions.AirflowException: Bash command failed. The command returned a non-zero exit code 1.
[2022-10-20 15:32:22,399] {taskinstance.py:1400} INFO - Marking task as FAILED. dag_id=1_init_once_seed_data, task_id=load_seed_data_once, execution_date=20221020T153217, start_date=20221020T153220, end_date=20221020T153222
[2022-10-20 15:32:22,494] {standard_task_runner.py:97} ERROR - Failed to execute job 12 for task load_seed_data_once (Bash command failed. The command returned a non-zero exit code 1.; 1454)
[2022-10-20 15:32:22,592] {local_task_job.py:156} INFO - Task exited with return code 1
[2022-10-20 15:32:22,873] {local_task_job.py:273} INFO - 0 downstream tasks scheduled from follow-on schedule check
