[2022-10-21 14:37:00,922] {taskinstance.py:1159} INFO - Dependencies all met for <TaskInstance: 1_init_once_seed_data.load_seed_data_once manual__2022-10-21T14:36:27.882107+00:00 [queued]>
[2022-10-21 14:37:01,029] {taskinstance.py:1159} INFO - Dependencies all met for <TaskInstance: 1_init_once_seed_data.load_seed_data_once manual__2022-10-21T14:36:27.882107+00:00 [queued]>
[2022-10-21 14:37:01,030] {taskinstance.py:1356} INFO - 
--------------------------------------------------------------------------------
[2022-10-21 14:37:01,031] {taskinstance.py:1357} INFO - Starting attempt 1 of 1
[2022-10-21 14:37:01,037] {taskinstance.py:1358} INFO - 
--------------------------------------------------------------------------------
[2022-10-21 14:37:01,274] {taskinstance.py:1377} INFO - Executing <Task(BashOperator): load_seed_data_once> on 2022-10-21 14:36:27.882107+00:00
[2022-10-21 14:37:01,301] {standard_task_runner.py:79} INFO - Running: ['***', 'tasks', 'run', '1_init_once_seed_data', 'load_seed_data_once', 'manual__2022-10-21T14:36:27.882107+00:00', '--job-id', '98', '--raw', '--subdir', 'DAGS_FOLDER/init.py', '--cfg-path', '/tmp/tmppiz1wxj0', '--error-file', '/tmp/tmpotbcpb8e']
[2022-10-21 14:37:01,304] {standard_task_runner.py:80} INFO - Job 98: Subtask load_seed_data_once
[2022-10-21 14:37:01,293] {standard_task_runner.py:52} INFO - Started process 401 to run task
[2022-10-21 14:37:20,966] {task_command.py:369} INFO - Running <TaskInstance: 1_init_once_seed_data.load_seed_data_once manual__2022-10-21T14:36:27.882107+00:00 [running]> on host 4bc03738798c
[2022-10-21 14:37:23,664] {taskinstance.py:1571} INFO - Exporting the following env vars:
AIRFLOW_CTX_DAG_OWNER=***
AIRFLOW_CTX_DAG_ID=1_init_once_seed_data
AIRFLOW_CTX_TASK_ID=load_seed_data_once
AIRFLOW_CTX_EXECUTION_DATE=2022-10-21T14:36:27.882107+00:00
AIRFLOW_CTX_TRY_NUMBER=1
AIRFLOW_CTX_DAG_RUN_ID=manual__2022-10-21T14:36:27.882107+00:00
[2022-10-21 14:37:23,668] {subprocess.py:62} INFO - Tmp dir root location: 
 /tmp
[2022-10-21 14:37:23,688] {subprocess.py:74} INFO - Running command: ['bash', '-c', 'cd /dbt && dbt seed --profiles-dir .']
[2022-10-21 14:37:23,757] {subprocess.py:85} INFO - Output:
[2022-10-21 14:37:23,773] {subprocess.py:92} INFO - bash: line 1: dbt: command not found
[2022-10-21 14:37:23,776] {subprocess.py:96} INFO - Command exited with return code 127
[2022-10-21 14:37:23,954] {taskinstance.py:1889} ERROR - Task failed with exception
Traceback (most recent call last):
  File "/home/airflow/.local/lib/python3.7/site-packages/airflow/operators/bash.py", line 195, in execute
    f'Bash command failed. The command returned a non-zero exit code {result.exit_code}.'
airflow.exceptions.AirflowException: Bash command failed. The command returned a non-zero exit code 127.
[2022-10-21 14:37:24,007] {taskinstance.py:1400} INFO - Marking task as FAILED. dag_id=1_init_once_seed_data, task_id=load_seed_data_once, execution_date=20221021T143627, start_date=20221021T143700, end_date=20221021T143724
[2022-10-21 14:37:24,185] {standard_task_runner.py:97} ERROR - Failed to execute job 98 for task load_seed_data_once (Bash command failed. The command returned a non-zero exit code 127.; 401)
[2022-10-21 14:37:24,280] {local_task_job.py:156} INFO - Task exited with return code 1
[2022-10-21 14:37:24,417] {local_task_job.py:273} INFO - 0 downstream tasks scheduled from follow-on schedule check
