[2022-10-21 15:45:55,601] {taskinstance.py:1159} INFO - Dependencies all met for <TaskInstance: 1_init_once_seed_data.load_seed_data_once manual__2022-10-21T15:44:45.551339+00:00 [queued]>
[2022-10-21 15:46:14,897] {taskinstance.py:1159} INFO - Dependencies all met for <TaskInstance: 1_init_once_seed_data.load_seed_data_once manual__2022-10-21T15:44:45.551339+00:00 [queued]>
[2022-10-21 15:46:17,426] {taskinstance.py:1356} INFO - 
--------------------------------------------------------------------------------
[2022-10-21 15:46:17,439] {taskinstance.py:1357} INFO - Starting attempt 1 of 1
[2022-10-21 15:46:19,183] {taskinstance.py:1358} INFO - 
--------------------------------------------------------------------------------
[2022-10-21 15:46:28,954] {taskinstance.py:1377} INFO - Executing <Task(BashOperator): load_seed_data_once> on 2022-10-21 15:44:45.551339+00:00
[2022-10-21 15:46:31,403] {standard_task_runner.py:79} INFO - Running: ['***', 'tasks', 'run', '1_init_once_seed_data', 'load_seed_data_once', 'manual__2022-10-21T15:44:45.551339+00:00', '--job-id', '106', '--raw', '--subdir', 'DAGS_FOLDER/init.py', '--cfg-path', '/tmp/tmpfb7kq_44', '--error-file', '/tmp/tmpqti5g5zz']
[2022-10-21 15:46:31,400] {standard_task_runner.py:52} INFO - Started process 180 to run task
[2022-10-21 15:46:31,435] {standard_task_runner.py:80} INFO - Job 106: Subtask load_seed_data_once
[2022-10-21 15:46:37,001] {task_command.py:369} INFO - Running <TaskInstance: 1_init_once_seed_data.load_seed_data_once manual__2022-10-21T15:44:45.551339+00:00 [running]> on host 817b8ef424b0
[2022-10-21 15:46:38,553] {taskinstance.py:1571} INFO - Exporting the following env vars:
AIRFLOW_CTX_DAG_OWNER=***
AIRFLOW_CTX_DAG_ID=1_init_once_seed_data
AIRFLOW_CTX_TASK_ID=load_seed_data_once
AIRFLOW_CTX_EXECUTION_DATE=2022-10-21T15:44:45.551339+00:00
AIRFLOW_CTX_TRY_NUMBER=1
AIRFLOW_CTX_DAG_RUN_ID=manual__2022-10-21T15:44:45.551339+00:00
[2022-10-21 15:46:39,346] {subprocess.py:62} INFO - Tmp dir root location: 
 /tmp
[2022-10-21 15:46:40,314] {subprocess.py:74} INFO - Running command: ['bash', '-c', 'cd /dbt && dbt seed --profiles-dir .']
[2022-10-21 15:46:41,495] {subprocess.py:85} INFO - Output:
[2022-10-21 15:46:41,675] {subprocess.py:92} INFO - bash: line 1: dbt: command not found
[2022-10-21 15:46:42,385] {subprocess.py:96} INFO - Command exited with return code 127
[2022-10-21 15:46:42,941] {taskinstance.py:1889} ERROR - Task failed with exception
Traceback (most recent call last):
  File "/home/airflow/.local/lib/python3.7/site-packages/airflow/operators/bash.py", line 195, in execute
    f'Bash command failed. The command returned a non-zero exit code {result.exit_code}.'
airflow.exceptions.AirflowException: Bash command failed. The command returned a non-zero exit code 127.
[2022-10-21 15:47:07,532] {taskinstance.py:1400} INFO - Marking task as FAILED. dag_id=1_init_once_seed_data, task_id=load_seed_data_once, execution_date=20221021T154445, start_date=20221021T154613, end_date=20221021T154707
[2022-10-21 15:47:37,858] {standard_task_runner.py:97} ERROR - Failed to execute job 106 for task load_seed_data_once (Bash command failed. The command returned a non-zero exit code 127.; 180)
[2022-10-21 15:47:40,310] {local_task_job.py:156} INFO - Task exited with return code 1
[2022-10-21 15:47:48,353] {local_task_job.py:273} INFO - 0 downstream tasks scheduled from follow-on schedule check
